<?xml version='1.0' encoding='UTF-8'?>
<robot name="jaka_leap_hand_robot">
  <link name="Link_0">
    <inertial>
      <origin xyz="-0.000169872459617813 -2.36448827889745e-08 0.0132846923173683" rpy="0.0 0.0 0.0"/>
      <mass value="0.76174"/>
      <inertia ixx="0.000673719313504642" ixy="-1.30755705487849e-08" ixz="-1.3262407834936e-06" iyy="0.000666781851440875" iyz="-1.80735801539484e-11" izz="0.00123663316539255"/>
    </inertial>
    <visual>
      <geometry>
        <mesh filename="meshes/jaka/Link0.STL"/>
      </geometry>
      <material name="Link_0_material"/>
      <origin xyz="0.0 0.0 0.0" rpy="0.0 0.0 0.0"/>
    </visual>
    <collision>
      <geometry>
        <mesh filename="meshes/jaka/Link0.STL"/>
      </geometry>
      <origin xyz="0.0 0.0 0.0" rpy="0.0 0.0 0.0"/>
    </collision>
  </link>
  <link name="Link_1">
    <inertial>
      <origin xyz="-1.99985037409469e-06 0.0134079971540169 -0.061631393869219" rpy="0.0 0.0 0.0"/>
      <mass value="3.1571"/>
      <inertia ixx="0.0128375469787325" ixy="2.28361925094216e-07" ixz="5.81760635898215e-08" iyy="0.0126762000445666" iyz="-0.00161037595218336" izz="0.00390574573183596"/>
    </inertial>
    <visual>
      <geometry>
        <mesh filename="meshes/jaka/Link1.STL"/>
      </geometry>
      <material name="Link_1_material"/>
      <origin xyz="0.0 0.0 0.0" rpy="0.0 0.0 0.0"/>
    </visual>
    <collision>
      <geometry>
        <mesh filename="meshes/jaka/Link1.STL"/>
      </geometry>
      <origin xyz="0.0 0.0 0.0" rpy="0.0 0.0 0.0"/>
    </collision>
  </link>
  <link name="Link_2">
    <inertial>
      <origin xyz="0.090613 -1.3771e-06 0.0043964" rpy="0.0 0.0 0.0"/>
      <mass value="1.0141"/>
      <inertia ixx="0.0019174" ixy="6.2208e-07" ixz="0.0022687" iyy="0.0073149" iyz="-3.3214e-07" izz="0.0064681"/>
    </inertial>
    <visual>forearm_index
      <geometry>
        <mesh filename="meshes/jaka/Link2.STL"/>
      </geometry>
      <material name="Link_2_material"/>
      <origin xyz="0.0 0.0 0.0" rpy="0.0 0.0 0.0"/>
    </visual>
    <collision>
      <geometry>
        <mesh filename="meshes/jaka/Link2.STL"/>
      </geometry>
      <origin xyz="0.0 0.0 0.0" rpy="0.0 0.0 0.0"/>
    </collision>
  </link>
  <link name="Link_3">
    <inertial>
      <origin xyz="-2.836e-07 0.042086 0.012428" rpy="0.0 0.0 0.0"/>
      <mass value="2.018"/>
      <inertia ixx="0.0055107" ixy="2.2287e-08" ixz="-3.4784e-08" iyy="0.0017496" iyz="0.0005528" izz="0.0052708"/>
    </inertial>
    <visual>
      <geometry>
        <mesh filename="meshes/jaka/Link3.STL"/>
      </geometry>
      <material name="Link_3_material"/>
      <origin xyz="0.0 0.0 0.0" rpy="0.0 0.0 0.0"/>
    </visual>
    <collision>
      <geometry>
        <mesh filename="meshes/jaka/Link3.STL"/>
      </geometry>
      <origin xyz="0.0 0.0 0.0" rpy="0.0 0.0 0.0"/>
    </collision>
  </link>
  <link name="Link_4">
    <inertial>
      <origin xyz="-5.23366787087349e-06 0.025945911865393 -0.0349284126752025" rpy="0.0 0.0 0.0"/>
      <mass value="0.412340000009804"/>
      <inertia ixx="0.000648308078586465" ixy="2.01279577389176e-08" ixz="-2.91846428270101e-08" iyy="0.000622438484108618" iyz="-0.000147788635079694" izz="0.000313549566736677"/>
    </inertial>
    <visual>
      <geometry>
        <mesh filename="meshes/jaka/Link4.STL"/>
      </geometry>
      <material name="Link_4_material"/>
      <origin xyz="0.0 0.0 0.0" rpy="0.0 0.0 0.0"/>
    </visual>
    <collision>
      <geometry>
        <mesh filename="meshes/jaka/Link4.STL"/>
      </geometry>
      <origin xyz="0.0 0.0 0.0" rpy="0.0 0.0 0.0"/>
    </collision>
  </link>
  <link name="Link_5">
    <inertial>
      <origin xyz="8.7254e-06 0.044553 0.010268" rpy="0.0 0.0 0.0"/>
      <mass value="1.6793"/>
      <inertia ixx="0.0040718" ixy="4.0506e-07" ixz="1.0998e-07" iyy="0.0013014" iyz="0.00040116" izz="0.0039042"/>
    </inertial>
    <visual>
      <geometry>
        <mesh filename="meshes/jaka/Link5.STL"/>
      </geometry>
      <material name="Link_5_material"/>
      <origin xyz="0.0 0.0 0.0" rpy="0.0 0.0 0.0"/>
    </visual>
    <collision>
      <geometry>
        <mesh filename="meshes/jaka/Link5.STL"/>
      </geometry>
      <origin xyz="0.0 0.0 0.0" rpy="0.0 0.0 0.0"/>
    </collision>
  </link>
  <link name="Link_6">
    <inertial>
      <origin xyz="-2.33954680956047e-05 3.42676856690269e-05 -0.0202928698270544" rpy="0.0 0.0 0.0"/>
      <mass value="0.311970001247665"/>
      <inertia ixx="0.00014377819366" ixy="-8.50913479195225e-07" ixz="-2.37501745813128e-07" iyy="0.000142682702873271" iyz="-3.26920852568197e-08" izz="0.000221812602025683"/>
    </inertial>
    <visual>
      <geometry>
        <mesh filename="meshes/jaka/Link6.STL"/>
      </geometry>
      <material name="Link_6_material"/>
      <origin xyz="0.0 0.0 0.0" rpy="0.0 0.0 0.0"/>
    </visual>
    <collision>
      <geometry>
        <mesh filename="meshes/jaka/Link6.STL"/>
      </geometry>
      <origin xyz="0.0 0.0 0.0" rpy="0.0 0.0 0.0"/>
    </collision>
  </link>

  <joint name="joint_1" type="revolute">
    <limit effort="100.0" velocity="1.57" lower="-6.28" upper="6.28"/>
    <parent link="Link_0"/>
    <child link="Link_1"/>
    <axis xyz="0. 0. 1."/>
    <origin xyz="0.0 0.0 0.187" rpy="0.0 0.0 0.0"/>
  </joint>
  <joint name="joint_2" type="revolute">
    <limit effort="100.0" velocity="1.57" lower="-2.09" upper="2.09"/>
    <parent link="Link_1"/>
    <child link="Link_2"/>
    <axis xyz="0. 0. 1."/>
    <origin xyz="0.0 -0.006 0.0" rpy="-1.5707926535897934 -1.5707926535755432 -3.141592653589793"/>
  </joint>
  <joint name="joint_3" type="revolute">
    <limit effort="100.0" velocity="1.57" lower="-2.27" upper="2.27"/>
    <parent link="Link_2"/>
    <child link="Link_3"/>
    <axis xyz="0. 0. 1."/>
    <origin xyz="0.21 0.0 0.0" rpy="0.0 0.0 -1.5708"/>
  </joint>
  <joint name="joint_4" type="revolute">
    <limit effort="100.0" velocity="1.57" lower="-6.28" upper="6.28"/>
    <parent link="Link_3"/>
    <child link="Link_4"/>
    <axis xyz="0. 0. 1."/>
    <origin xyz="0.0 0.2105 0.0" rpy="-1.5708 0.0 0.0"/>
  </joint>
  <joint name="joint_5" type="revolute">
    <limit effort="100.0" velocity="1.57" lower="-2.09" upper="2.09"/>
    <parent link="Link_4"/>
    <child link="Link_5"/>
    <axis xyz="0. 0. 1."/>
    <origin xyz="0.0 0.0 0.0" rpy="1.5708 0.0 0.0"/>
  </joint>
  <joint name="joint_6" type="revolute">
    <limit effort="100.0" velocity="1.57" lower="-6.28" upper="6.28"/>
    <parent link="Link_5"/>
    <child link="Link_6"/>
    <axis xyz="0. 0. 1."/>
    <origin xyz="0.0 0.1593 0.0" rpy="-1.5708 0.0 0.0"/>
  </joint>
</robot>
